Workbook

Sheet 产品类型库
A1: 排序 | B1: 一级标签 | C1: 二级标签
A2: 1 | B2: 流量包 | C2: 瞬时流量
A3: 2 | B3: 流量包 | C3: 定向流量
A4: 3 | B4: 流量包 | C4: 区域流量
A5: 4 | B5: 流量包 | C5: 流量年包
A6: 5 | B6: 归位包 | C6: 归位包
A7: 6 | B7: 新业务 | C7: 视频彩铃
A8: 7 | B8: 新业务 | C8: 移动云盘
A9: 8 | B9: 权益 | C9: 黑卡
A10: 9 | B10: 权益 | C10: 随心选生态券
A11: 10 | B11: 资费 | C11: 潮玩卡
A12: 11 | B12: 资费 | C12: 视频卡
A13: 12 | B13: 资费合约 | C13: 终端合约
... A15: 14 | B15: 资费合约 | C15: 套餐打折

Sheet 产品库
A1: 排序 | B1: 产品类型 | C1: 产品名称 | D1: 产品档位 | E1: 产品介绍
B2: 定向流量 | C2: 前三月1元15G定向流量包（抖音） | D2: 1元 | E2: 前三个月1元抖音15GB定向体验包，第四个月恢复原价9元，限制客户12个月内只能订购一次1元体验包。
B3: 定向流量 | C3: 前三月1元15G定向流量包（快手） | D3: 1元 | E3: 前三个月1元快手15GB定向体验包，第四个月恢复原价9元，限制客户12个月内只能订购一次1元体验包。
B4: 定向流量 | C4: 前三月1元30G定向流量包（抖音） | D4: 1元 | E4: 前三个月1元抖音30GB定向体验包，第四个月恢复原价19元，限制客户12个月内只能订购一次1元体验包。
B5: 定向流量 | C5: 前三月1元30G定向流量包（快手） | D5: 1元 | E5: 前三个月1元快手30GB定向体验包，第四个月恢复原价19元，限制客户12个月内只能订购一次1元体验包。 | F5: 产品类型列内容必须严格与产品类型库二级标签保持一致
B6: 定向流量 | C6: 0元70GB农村定向流量包（抖音+快手） | D6: 0元 | E6: 产品包含70GB鄂尔多斯区域抖音+快手定向流量，仅78元及以上资费可选择订购，产品包账期24个月，到期自动失效，流量优先级614，流量不可结转、不可共享。
B7: 定向流量 | C7: 0元50GB农村定向流量包（抖音+快手） | D7: 0元 | E7: 产品包含50GB鄂尔多斯区域抖音+快手定向流量，仅58元资费可选择订购，产品包账期24个月，到期自动失效，流量优先级614，流量不可结转、不可共享。
B8: 定向流量 | C8: 0元30GB农村定向流量包（抖音+快手） | D8: 0元 | E8: 产品包含30GB鄂尔多斯区域抖音+快手定向流量，仅38元资费可选择订购，产品包账期24个月，到期自动失效，流量优先级614，流量不可结转、不可共享。
B9: 定向流量 | C9: 9元15G定向流量包（抖音） | D9: 9元 | E9: 包含抖音30GB定向体验包，流量不可结转、不可共享。
B10: 定向流量 | C10: 9元15G定向流量包（快手） | D10: 9元 | E10: 包含快手30GB定向体验包，流量不可结转、不可共享。
B11: 流量年包 | C11: 150元240GB抖音+快手流量年包-鄂尔多斯 | D11: 150元 | E11: 产品包含15GB全国通用流量+225GB抖音+快手定向流量，150元费用一次性收取，流量资源一次性提供，流量年包账期12个月，到期自动失效，年包内通用流量优先级100，抖音+快手专属流量优先级810，定向流量不含直播。流量不可共享。
B12: 流量年包 | C12: 200元360GB抖音+快手流量年包-鄂尔多斯 | D12: 200元 | E12: 产品包含20GB全国通用流量+340GB抖音+快手定向流量，200元费用一次性收取，流量资源一次性提供，流量年包账期12个月，到期自动失效，年包内通用流量优先级100，抖音+快手专属流量优先级810，定向流量不含直播。流量不可共享。
B13: 区域流量 | C13: 3元20GB农村区域流量包-鄂尔多斯 | D13: 3元 | E13: 存量农村客户套餐升档28元及以上可办理3元20GB区域流量包，20GB鄂尔多斯区域流量、不共享、不结转、流量优先级580、账期12个月。
B14: 区域流量 | C14: 1元30GB农村区域流量包-鄂尔多斯 | D14: 1元 | E14: 产品包含30GB鄂尔多斯区域流量，产品包账期24个月，到期自动失效，流量优先级580，流量不可结转、不可共享。
B15: 区域流量 | C15: 1元50GB农村区域流量包-鄂尔多斯 | D15: 1元 | E15: 产品包含50GB鄂尔多斯区域流量，产品包账期24个月，到期自动失效，流量优先级580，流量不可结转、不可共享。
B16: 区域流量 | C16: 1元70GB农村区域流量包-鄂尔多斯 | D16: 1元 | E16: 产品包含70GB鄂尔多斯区域流量，产品包账期24个月，到期自动失效，流量优先级580，流量不可结转、不可共享。
B17: 瞬时流量 | C17: 小时包（4小时）2元1GB | D17: 2元 | E17: 通用流量，4小时，一月最多30次
... B63: 话费合约 | C63: 159元资费月返47元话费金币活动（24个月） | D63: 159元 | E63: 159元资费月返47元金币活动（24个月）
B64: 套餐打折 | C64: 全家享99元套餐打七折（24个月） | D64: 99 | E64: 全家享99元套餐打七折（24个月）
B65: 套餐打折 | C65: 全家享129元套餐打七折（24个月） | D65: 129 | E65: 全家享129元套餐打七折（24个月）
B66: 套餐打折 | C66: 全家享159元套餐打七折（24个月） | D66: 159 | E66: 全家享159元套餐打七折（24个月）
B67: 套餐打折 | C67: 全家享199元套餐打七折（24个月） | D67: 199 | E67: 全家享199元套餐打七折（24个月）
B68: 套餐打折 | C68: 全家享239元套餐打七折（24个月） | D68: 239 | E68: 全家享239元套餐打七折（24个月）
B69: 套餐打折 | C69: 全家享299元套餐打七折（24个月） | D69: 299 | E69: 全家享299元套餐打七折（24个月）
B70: 套餐打折 | C70: 全家享399元套餐打七折（24个月） | D70: 399 | E70: 全家享399元套餐打七折（24个月）

Sheet 场景名称库
A1: 排序 | B1: 难度 | C1: 类型 | D1: 场景名称 | E1: 场景介绍 | F1: 推荐产品1 | G1: 推荐产品2 | H1: 推荐产品3 | I1: 推荐产品4 | J1: 推荐产品5 | K1: 推荐产品6
A2: 1 | B2: 10 | C2: 个人 | D2: 流量激发 | E2: 聚焦流量需求客户，细分场景精准运营瞬时包、定向包等，激发客户流量使用需求。 | F2: 前三月1元15G定向流量包（抖音）
A3: 2 | B3: 10 | C3: 个人 | D3: 新业务 | E3: 新业务场景，深挖客户痛点，满足客户产品使用需求，借助产品核心卖点，提升客户价值贡献。 | F3: 移动云盘白银会员(连续包月) | G3: 5G特色视频彩铃包
A4: 3 | B4: 10 | C4: 个人 | D4: 新入网场景 | E4: 新入网场景，针对不同年龄不同行业的用户，紧抓触点，实现高质量新入网，通过积极融合保障用户长期在网 | F4: 69元视频卡
A5: 4 | B5: 10 | C5: 个人 | D5: 高套潜在升档运营 | E5: 针对高价值、流量使用饱和度高的用户，开展相关运营，进一步激发流量使用的同时，提高用户价值。 | F5: 99元资费月返29元话费金币活动（24个月） | G5: 黑卡PLUS会员
A6: 5 | B6: 10 | C6: 个人 | D6: 终端换机客户 | E6: 终端换机场景，针对使用手机已达到两年及以上，并且根据不同年龄，不同职业、不同消费，以及对手机的需求，推荐办理不同档位的终端合约。 | F6: 159元资费月返47元金币活动（24个月） | G6: 前三月1元15G定向流量包（抖音）
A7: 6 | B7: 15 | C7: 个人 | D7: 流量运营 | E7: 针对抖音、快手APP偏好客户推广抖音、快手流量年包，满足客户上网需求，实现流量、价值双提升。 | F7: 150元240GB抖音+快手流量年包-鄂尔多斯
A8: 7 | B8: 15 | C8: 个人 | D8: 到期续约 | E8: 针对次月优惠活动到期客户 | F8: 全家享99元套餐打七折（24个月） | G8: 79元资费月返23元金币活动（24个月）
A9: 8 | B9: 15 | C9: 个人 | D9: 重点客户赢回场景 | E9: 针对异网高价值、有宽带资源、有我网家属的异网客户 | F9: 79元资费月返23元话费金币活动（24个月） | G9: 黑卡PLUS会员 | H9: 5G特色视频彩铃包
A10: 9 | B10: 15 | C10: 个人 | D10: 农村场景 | E10: 针对农村场景融合运营，打破农村客户流量不敢用、不够用的困局。 | F10: 58元资费月返17元话费金币活动（24个月） | G10: 3元20GB农村区域流量包-鄂尔多斯 | H10: 1元30GB农村区域流量包-鄂尔多斯
A11: 10 | B11: 15 | C11: 个人 | D11: 潜在流失场景 | E11: 针对潜在流失客户，开展关怀挽留运营，根据客户使用语音、流量属性开展适配关怀活动，降低客户潜在流失风险。 | F11: 29元归位包 | G11: 黑卡PLUS会员
A12: 11 | B12: 20 | C12: 个人 | D12: 年轻人场景 | E12: 因年轻人市场尾部用户较多，特针对年轻人市场低消用户开展运营，激发年轻人用户活性，赢回年轻人用户流量使用习惯。 | F12: 58元资费月返17元话费金币活动（24个月） | G12: 黑卡PLUS会员 | H12: 3元20GB农村区域流量包-鄂尔多斯
A13: 12 | B13: 20 | C13: 个人 | D13: 终端高饱和场景 | E13: 终端高饱和场景，针对使用终端且使用语音流量饱和度较高，根据不同消费和职业，推荐办理不同档位手机终端，并且也可以提升套餐内的语音和流量。 | F13: 79元资费月返23元金币活动（24个月） | G13: 159元资费月返47元金币活动（24个月） | H13: 前三月1元15G定向流量包（抖音）
A14: 13 | B14: 20 | C14: 个人 | D14: 套餐适配运营 | E14: 针对套餐不适配、潜在不满客户开展关怀运营，根据用户使用流量、语音等相关情况，开展适配运营活动，提高客户套餐适配性，提升客户满意度。 | F14: 58元资费月返17元话费金币活动（24个月） | G14: 前三月1元15G定向流量包（抖音）
A15: 14 | B15: 20 | C15: 个人 | D15: 校园场景 | E15: 校园场景，针对即将入校、入校新生等不同校园用户，通过触点营销，实现高质量新入网，保障用户长期在网 | F15: 动感地带潮玩卡资费-59元 | G15: 移动云盘内蒙古套餐空间包(200G+200G）
A16: 15 | B16: 20 | C16: 个人 | D16: 异网主卡赢回场景 | E16: 针对异网主卡用户，开展赢回运营，深挖用户语音、流量需求，并为其制定配套的打包政策。 | F16: 58元资费月返17元话费金币活动（24个月） | G16: 前三月1元15G定向流量包（抖音）

Sheet 客户画像库
A1: 排序 | B1: 场景名称 | C1: 客户名称 | D1: 人设 | E1: 性别 | F1: 合约 | G1: 价值 | H1: 年龄 | I1: 流量 | J1: 资费 | K1: 融合 | L1: 视频偏好 | M1: 权益 | N1: 职业 | O1: 地域
A2: 1 | B2: =[1]场景名称库!D2 -> 流量激发 | C2: 客户1 | D2: 全职妈妈 | E2: 女 | F2: 无合约 | G2: 有价值客户 | H2: 25-40 | I2: 20-40GB | J2: 58-98元新资费 | K2: 0度客户 | L2: 抖音 | M2: 无 | N2: =D2 -> 全职妈妈 | O2: 城区
A3: 2 | C3: 客户2 | D3: 在校大学生 | E3: 男 | F3: 无合约 | G3: 有价值用户 | H3: 16-25 | I3: 40GB以上 | J3: 58-98元新资费 | K3: 0度客户 | L3: 抖音 | M3: 无 | N3: =D3 -> 在校大学生 | O3: 城区
A4: 3 | C4: 客户3 | D4: 职场青年 | E4: 女 | F4: 无合约 | G4: 有价值用户 | H4: 25-40 | I4: 20-40GB | J4: 58-98元新资费 | K4: 0度客户 | L4: 抖音 | M4: 无 | N4: =D4 -> 职场青年 | O4: 城区
A5: 4 | C5: 客户4 | D5: 商务人士 | E5: 男 | F5: 无合约 | G5: 有价值用户 | H5: 40-60 | I5: 20-40GB | J5: 98元以上新资费 | K5: 0度客户 | L5: 抖音 | M5: 无 | N5: =D5 -> 商务人士 | O5: 城区
A6: 5 | C6: 客户5 | D6: 集团AB类用户 | E6: 男 | F6: 无合约 | G6: 有价值用户 | H6: 25-40 | I6: 40GB以上 | J6: 98元以上新资费 | K6: 0度客户 | L6: 抖音 | M6: 无 | N6: =D6 -> 集团AB类用户 | O6: 城区
A7: 6 | C7: 客户6 | D7: 个体工商户 | E7: 男 | F7: 无合约 | G7: 有价值用户 | H7: 25-40 | I7: 20-40GB | J7: 98元以上新资费 | K7: 0度客户 | L7: 抖音 | M7: 无 | N7: =D7 -> 个体工商户 | O7: 城区
A8: 2 | B8: =[1]场景名称库!D3 -> 新业务 | C8: 客户1 | D8: 集团AB类用户 | E8: 男 | F8: 无合约 | G8: 高价值客户 | H8: 25-40 | I8: 12G-20G | J8: 58元以下新资费 | K8: 0度客户 | L8: 无 | M8: 无 | N8: =D8 -> 集团AB类用户 | O8: 城区
A9: 8 | C9: 客户2 | D9: 个体工商户 | E9: 男 | F9: 无合约 | G9: 高价值客户 | H9: 25-40 | I9: 12G-20G | J9: 58元以下新资费 | K9: 0度客户 | L9: 无 | M9: 视频彩铃权益已领取未活跃 | N9: =D9 -> 个体工商户 | O9: 城区
A10: 9 | C10: 客户3 | D10: 抖音、快手偏好客户 | E10: 男 | F10: 无合约 | G10: 有价值客户 | H10: 25-40 | I10: 12G-20G | J10: 58元以下新资费 | K10: 0度客户 | L10: 无 | M10: 无 | N10: =D10 -> 抖音、快手偏好客户 | O10: 城区
A11: 10 | C11: 客户4 | D11: 全职妈妈 | E11: 女 | F11: 无合约 | G11: 有价值客户 | H11: 25-40 | J11: 58元以下新资费 | K11: 0度客户 | L11: 无 | M11: 移动云盘权益已领取未活跃 | N11: =D11 -> 全职妈妈 | O11: 城区
A12: 11 | C12: 客户5 | D12: 在校大学生 | E12: 男 | F12: 无合约 | G12: 有价值客户 | H12: 16-25 | J12: 58元以下新资费 | K12: 0度客户 | L12: 无 | M12: 无 | N12: =D12 -> 在校大学生 | O12: 城区
A13: 12 | C13: 客户6 | D13: 务工人员 | E13: 女 | F13: 无合约 | G13: 有价值客户 | H13: 25-40 | I13: 6G-12G | J13: 58元以下新资费 | K13: 0度客户 | L13: 无 | M13: 无 | N13: =D13 -> 务工人员 | O13: 城区
A14: 3 | B14: =[1]场景名称库!D4 -> 新入网场景 | C14: 客户1 | D14: 职场青年 | E14: 男 | F14: 无合约 | G14: 有价值客户 | H14: 25-40 | I14: 20-40G | J14: 58元以下新资费 | K14: 0度客户 | L14: 抖音、爱优腾芒 | M14: 无 | N14: =D14 -> 职场青年 | O14: 城区
A15: 14 | C15: 客户2 | D15: 高龄独居老人 | E15: 女 | F15: 强合约 | G15: 高价值客户 | H15: 40-60 | I15: 12G-20G | J15: 他网58-99元新资费 | K15: 0度客户 | L15: 抖音 | M15: 黑卡权益已领取未激活 | N15: =D15 -> 高龄独居老人 | O15: 城区
A16: 15 | C16: 客户3 | D16: 务工人员 | E16: 男 | F16: 无合约 | G16: 有价值客户 | H16: 25-40 | I16: 20-40G | J16: 老旧资费 | K16: 0度客户 | L16: 抖音 | M16: 无 | N16: =D16 -> 务工人员 | O16: 镇区
A17: 16 | C17: 客户4 | D17: 商务人士 | E17: 男 | F17: 强合约 | G17: 高价值客户 | H17: 25-40 | I17: 12G-20G | J17: 他网98元以上资费 | K17: 0度客户 | L17: 爱优腾芒 | M17: 无 | N17: =D17 -> 商务人士 | O17: 城区
A18: 17 | C18: 客户5 | D18: 高龄独居老人 | E18: 男 | F18: 弱合约 | G18: 有价值客户 | H18: 60岁以上 | I18: 12G-20G | J18: 他网58-98元新资费 | K18: 0度客户 | L18: 抖音 | M18: 无 | N18: =D18 -> 高龄独居老人 | O18: 城区
A19: 18 | C19: 客户6 | D19: 高中毕业生 | E19: 女 | F19: 弱合约 | G19: 有价值客户 | H19: 16-25 | I19: 40G以上） | J19: 58元以下新资费 | K19: 0度客户 | L19: 抖音、爱优腾芒 | M19: 无 | N19: =D19 -> 高中毕业生 | O19: 城区
A20: 4 | B20: 高价值高饱和客户 | C20: 客户1 | D20: 高龄独居老人 | E20: 男 | F20: 无合约 | G20: 有价值用户 | H20: 60岁以上 | I20: 12-20GB | J20: 58-98元新资费 | K20: 0度融合 | L20: 抖音 | M20: 无 | N20: =D20 -> 高龄独居老人 | O20: 城区
A21: 20 | C21: 客户2 | D21: 个体工商户 | E21: 男 | F21: 无合约 | G21: 有价值用户 | H21: 26-40 | I21: 12-20GB | J21: 58-98元新资费 | K21: 0度融合 | L21: 抖音 | M21: 无 | N21: =D21 -> 个体工商户 | O21: 城区
A22: 21 | C22: 客户3 | D22: 在校大学生 | E22: 男 | F22: 无合约 | G22: 有价值用户 | H22: 16-25 | I22: 12-20GB | J22: 58-98元新资费 | K22: 0度融合 | L22: 抖音 | M22: 无 | N22: =D22 -> 在校大学生 | O22: 城区
A23: 22 | C23: 客户4 | D23: 职场青年 | E23: 男 | F23: 无合约 | G23: 有价值用户 | H23: 25-40 | I23: 12-20GB | J23: 58-98元新资费 | K23: 0度融合 | L23: 抖音 | M23: 无 | N23: =D23 -> 职场青年 | O23: 城区
A24: 23 | C24: 客户5 | D24: 全职妈妈 | E24: 女 | F24: 无合约 | G24: 有价值用户 | H24: 25-40 | I24: 12-20GB | J24: 58-98元新资费 | K24: 0度融合 | L24: 抖音 | M24: 无 | N24: =D24 -> 全职妈妈 | O24: 城区
A25: 24 | C25: 客户6 | D25: 务工人员 | E25: 男 | F25: 无合约 | G25: 有价值用户 | H25: 25-40 | I25: 12-20GB | J25: 58-98元新资费 | K25: 0度融合 | L25: 抖音 | M25: 无 | N25: =D25 -> 务工人员 | O25: 城区
A26: 5 | B26: =[1]场景名称库!D6 -> 终端换机客户 | C26: 客户1 | D26: 高中毕业生 | E26: 女 | F26: 无合约 | G26: 价值用户 | H26: 16-25 | I26: 1G-6G | J26: 58元以下新资费 | K26: 0度客户 | L26: 抖音 | M26: 无 | N26: =D26 -> 高中毕业生 | O26: 城区
A27: 26 | C27: 客户2 | D27: 在校大学生 | E27: 男 | F27: 弱合约 | G27: 有价值用户 | H27: 16-25 | I27: 6G-12G | J27: 58-98元新资费 | K27: 3度以下客户 | L27: 抖音 | M27: 无 | N27: =D27 -> 在校大学生 | O27: 城区
A28: 27 | C28: 客户3 | D28: 职场青年 | E28: 男 | F28: 弱合约 | G28: 高价值用户 | H28: 25-40 | I28: 20-40G | J28: 98元及以上新资费 | K28: 3-5度以下客户 | L28: 抖音 | M28: 无 | N28: =D28 -> 职场青年 | O28: 城区
A29: 28 | C29: 客户4 | D29: 高龄独居老人 | E29: 男 | F29: 无合约 | G29: 价值用户 | H29: 40-60 | I29: 1G以下 | J29: 老旧资费 | K29: 0度客户 | L29: 抖音 | M29: 无 | N29: =D29 -> 高龄独居老人 | O29: 农村
A30: 29 | C30: 客户5 | D30: 在校大学生 | E30: 男 | F30: 无合约 | G30: 高价值用户 | H30: 16-25 | I30: 40G以上 | J30: 98元及以上新资费 | K30: 5度以上客户 | L30: 抖音 | M30: 无 | N30: =D30 -> 在校大学生 | O30: 城区
A31: 30 | C31: 客户6 | D31: 职场青年 | E31: 男 | F31: 无合约 | G31: 高价值用户 | H31: 25-40 | I31: 40G以上 | J31: 98元及以上新资费 | K31: 5度以上客户 | L31: 抖音 | M31: 无 | N31: =D31 -> 职场青年 | O31: 城区
A32: 6 | B32: =[1]场景名称库!D7 -> 流量运营 | C32: 客户1 | D32: 全职妈妈 | E32: 女 | F32: 无合约 | G32: 有价值客户 | H32: 25-40 | I32: 20-40GB | J32: 58-98元新资费 | K32: 0度客户 | L32: 抖音 | M32: 无 | N32: =D32 -> 全职妈妈 | O32: 城区
A33: 32 | C33: 客户2 | D33: 抖音、快手偏好客户 | E33: 女 | F33: 无合约 | G33: 有价值用户 | H33: 16-25 | I33: 40GB以上 | J33: 58-98元新资费 | K33: 0度客户 | L33: 抖音 | M33: 无 | N33: =D33 -> 抖音、快手偏好客户 | O33: 城区
A34: 33 | C34: 客户3 | D34: 职场青年 | E34: 女 | F34: 无合约 | G34: 有价值用户 | H34: 25-40 | I34: 20-40GB | J34: 58-98元新资费 | K34: 0度客户 | L34: 抖音 | M34: 无 | N34: =D34 -> 职场青年 | O34: 城区
A35: 34 | C35: 客户4 | D35: 商务人士 | E35: 男 | F35: 无合约 | G35: 有价值用户 | H35: 40-60 | I35: 20-40GB | J35: 98元以上新资费 | K35: 0度客户 | L35: 抖音 | M35: 无 | N35: =D35 -> 商务人士 | O35: 城区
A36: 35 | C36: 客户5 | D36: 集团AB类用户 | E36: 男 | F36: 无合约 | G36: 有价值用户 | H36: 25-40 | I36: 40GB以上 | J36: 98元以上新资费 | K36: 0度客户 | L36: 抖音 | M36: 无 | N36: =D36 -> 集团AB类用户 | O36: 城区
A37: 36 | C37: 客户6 | D37: 个体工商户 | E37: 男 | F37: 无合约 | G37: 有价值用户 | H37: 25-40 | I37: 20-40GB | J37: 98元以上新资费 | K37: 0度客户 | L37: 抖音 | M37: 无 | N37: =D37 -> 个体工商户 | O37: 城区
A38: 7 | B38: =[1]场景名称库!D8 -> 到期续约 | C38: 客户1 | D38: 职场青年 | E38: 男 | F38: 强合约 | G38: 价值客户 | H38: 25-40 | I38: 12-20G | J38: 老旧资费 | K38: 0度融合 | L38: 无 | M38: 无 | N38: =D38 -> 职场青年 | O38: 城区
A39: 38 | C39: 客户2 | D39: 务工人员 | E39: 男 | F39: 强合约 | G39: 价值客户 | H39: 25-40 | I39: 40G以上 | J39: 98元以上新资费 | K39: 0度融合 | L39: 无 | M39: 无 | N39: =D39 -> 务工人员 | O39: 城区
A40: 39 | C40: 客户3 | D40: 全职妈妈 | E40: 女 | F40: 强合约 | G40: 高价值客户 | H40: 25-40 | I40: 40G以上 | J40: 98元以上新资费 | K40: 0度客户 | L40: 无 | M40: 黑卡权益已领取未激活 | N40: =D40 -> 全职妈妈 | O40: 城区
...

Sheet 问候对话池
A1: 排序 | B1: 触点名称 | C1: 类型 | D1: 内容1 | E1: 回复1 | F1: 得分1 | G1: 内容2 | H1: 回复2 | I1: 得分2
A2: 1 | B2: 外呼触点 | C2: 第一句 | D2: 您好，我是移动公司客户经理，我们现在有个优惠活动，给您介绍一下可以吗？ | E2: 不用了谢谢 | F2: 5 | G2: 您好领导，我是中国移动的客户经理，感谢您接听我的电话，我们今天是来为您推荐一款合适您的业务的。 | H2: 不用了，谢谢 | I2: 4
A3: 2 | B3: 外呼触点 | C3: 第一句 | D3: 您好，我是您的专属客户经理，根据您最近的消费和流量使用情况，为您申请了一套优惠的资费政策，我给您介绍一下吧。 | E3: 不用了 | F3: 5 | G3: 您好，我是您的专属客户经理，根据您最近的消费和流量使用情况，为您匹配了一项适合您的政策。 | H3: 不用了，不需要。 | I3: 4
A4: 3 | B4: 外呼触点 | C4: 第一句 | D4: 您好，我是您的专属客户经理，根据您最近的消费和流量使用情况，为您申请了一套优惠的资费政策，我给您介绍一下？ | E4: 不用啦 | F4: 5 | G4: 您好，我是您的专属客户经理，根据您最近的消费和流量使用情况，为您申请了一项适合您的政策。 | H4: 不用了，不需要。 | I4: 4
A5: 4 | B5: 外呼触点 | C5: 其他 | D5: 本次为您推荐的活动是根据您近期消费情况特殊申请的政策，较于您目前使用的资费合适很多，同时不会耽误您很长时间。 | E5: 好的 | F5: 5 | G5: 您近三个月的月均消费和月均DOU刚好符合我们为您推荐的政策，您不妨听我介绍一下。 | H5: 好的 | I5: 4
A6: 5 | B6: 外呼触点 | C6: 其他 | D6: 是这样的，这次活动优惠力度很大，只耽误您一分钟时间，您要是觉得不合适也可以不办啊，错过了挺可惜的! | E6: 行呢 | F6: 5 | G6: 我看您最近消费有些超套，我为您推荐的比较适合，要不您了解一下。 | H6: 行呢 | I6: 4
A7: 6 | B7: 外呼触点 | C7: 其他 | D7: 您可以先听我介绍一下，耽误您俩分钟了解一下，合适的话您可以办理，不合适的话您也可以选择其他的。 | E7: 可以 | F7: 5 | G7: 您近三个月的月均消费和月均DOU刚好符合我们为您推荐的政策，您不妨听我介绍一下。 | H7: 可以 | I7: 4
A8: 7 | B8: 入户触点 | C8: 第一句 | D8: 您好，我是您的移动专属客户经理，这次上门来是给您申请了一个合适的活动，耽误您几分钟时间为您介绍一下可以吗？ | E8: 可以，进来吧! | F8: 5 | G8: 您好，我是中国移动的客户经理，是来免费帮您查询话费的。 | H8: 进来吧 | I8: 4
A9: 8 | B9: 入户触点 | C9: 第一句 | D9: 您好，我是中国移动的客户经理，今天上门来是免费给您查询话费余额的。您看方便我进来吗？ | E9: 进来吧，家里就我一个人，没啥不方便的。 | F9: 5 | G9: 您好，我是移动公司客户经理，现在有个优惠活动需告知您。 | H9: 行吧 | I9: 4
A10: 10 | B10: 入户触点 | C10: 其他 | D10: 您告诉我一下手机号码，我给您查询一下吧。你们家可真干净，稍等下，我带个鞋套。 | E10: 好的。 | F10: 5 | G10: 您告诉我一下手机号码，我给您查询一下吧。 | H10: 好的。 | I10: 4
A11: 11 | B11: 入户触点 | C11: 其他 | D11: 你们家的装修风格很特别呀，是您自己设计的吗？您告诉我一下手机号码，我给您查询一下吧。 | E11: 好的。 | F11: 5 | G11: 您告诉我一下手机号码，我给您查询一下吧。 | H11: 好的。 | I11: 4
A12: 12 | B12: 进厅触点 | C12: 第一句 | D12: 您好，有什么需要我帮您办理的吗，您请坐，这边需要您先提供一下证件。 | E12: 好的。 | F12: 5 | G12: 您好，请问需要办理什么业务？ | H12: 我想办张卡。 | I12: 4
A13: 13 | B13: 进厅触点 | C13: 其他 | D13: 我们近期有一些比较合适的活动，您先看一下，然后我再给您详细绍一下。 | E13: 嗯嗯。 | F13: 5 | G13: 这些都是近期比较合适的活动，您可以先看看想办理哪个。 | H13: 行吧。 | I13: 4
... A15: 15 | B15: 集团触点 | C15: 其他 | D15: 我们近期推出了一些比较合适的活动，特意来给您介绍一下~ | E15: 真是谢谢你了，小李。 | F15: 5 | G15: 过来给您汇报一下新的活动。 | H15: 好的。 | I15: 4

Sheet 关怀对话池
A1: 排序 | B1: 客户名称 | C1: 人设 | D1: 触点1名称 | E1: 触点1销售 | F1: 触点1客户 | G1: 触点1得分 | H1: 触点2名称 | I1: 触点2销售 | J1: 触点2客户 | K1: 触点2得分 | L1: 触点3名称 | M1: 触点3销售 | N1: 触点3客户 | O1: 触点3得分
A2: 1 | B2: 场景1客户1 | C2: 全职妈妈 | D2: 外呼触点 | E2: 听您声音您好年轻呀，您是刚毕业吗？ | F2: 嘿嘿，谢谢夸奖，我都有俩个孩子了。 | G2: 5 | H2: 入户触点 | I2: 看您这么年轻，没想到竟然都是俩个孩子的妈妈了。俩个宝宝都这么可爱！ | J2: 嘿嘿，谢谢夸奖，是俩个淘气鬼。 | K2: 5
A3: 2 | B3: 场景1客户1 | C3: 全职妈妈 | D3: 外呼触点 | E3: 是吗？真是听不出来呀！还以为您是刚毕业呢！ | F3: 哈哈，您真会说话! | G3: 5 | H3: 入户触点 | I3: 俩个宝宝长得跟您真像啊，有这么可爱小宝宝，真是让人羡慕啊！ | J3: 哈哈，您真会说话! | K3: 5
A4: 3 | B4: 场景1客户2 | C4: 在校大学生 | D4: 外呼触点 | E4: 听你说话口音不是本地人吧，老家是哪里的呀?你是那个学校的？快毕业了吧？ | F4: 老家是东北的，我是农牧学校的，嗯，快了，现在在单位实习期 | G4: 5 | H4: 进厅触点 | I4: 你好，需要办理什么业务，看你好年轻啊，还在上学吧！ | J4: 嗯，还在上学，最近放假了 | K4: 5
A5: 4 | B5: 场景1客户2 | C5: 在校大学生 | D5: 外呼触点 | E5: 哦，太巧了，我妹妹也在你们学校。当时学校门口有个卖炸串的店是学生勤功俭学开的，现在还在吧？ | F5: 嗯，是的，味道不错 | G5: 5 | H5: 进厅触点 | I5: 哦，真好，有寒暑假，多出去转转看看 | J5: 嗯，过两天就出门。 | K5: 5
A6: 5 | B6: 场景1客户3 | C6: 职场青年 | D6: 外呼触点 | E6: 听你声音好年轻啊，你是学生还是工作了 | F6: 工作了 | G6: 5 | H6: 进厅触点 | I6: 看你好年轻啊，你还是学生吧 | J6: 不，已经工作了 | K6: 5
A7: 6 | B7: 场景1客户3 | C7: 职场青年 | D7: 外呼触点 | E7: 看您话费是有统付这些了，福利待遇挺好呀 | F7: 还行 | G7: 5 | H7: 进厅触点 | I7: 哦，看你套餐消费这么高，平时工作应该很忙。 | J7: 嗯，是的，工作比较忙 | K7: 5
A8: 7 | B8: 场景1客户4 | C8: 商务人士 | D8: 外呼触点 | E8: 领导您工作是不是挺忙的呀，平时出差是不是比较多。 | F8: 嗯，平时工作比较多。 | G8: 5 | H8: 进厅触点 | I8: 领导您工作是不是挺忙的呀，平时出差是不是比较多。 | J8: 嗯，平时工作比较多。 | K8: 5
A9: 8 | B9: 场景1客户4 | C9: 商务人士 | D9: 外呼触点 | E9: 那挺辛苦的，那我简短点给您介绍。 | F9: 好的 | G9: 5 | H9: 进厅触点 | I9: 那挺辛苦的，那我简短点给您介绍。 | J9: 好的 | K9: 5
A10: 9 | B10: 场景1客户5 | C10: 集团AB类用户 | D10: 集团触点 | E10: 你们的办公室可真大，办公环境真好。听您说话的口音好像不是本地人，您是哪里人呀？ | F10: 嗯，我是东北的赤峰的 | G10: 5 | H10: 外呼触点 | I10: 您好，我是中国移动的客户经理，看您语音流量都使用挺多的，最近工作是不是很忙？ | J10: 还行 | K10: 5
A11: 10 | B11: 场景1客户5 | C11: 集团AB类用户 | D11: 集团触点 | E11: 哦，太巧了，我是东北锡盟的，咱们也算是半个老乡啦，我是毕业后直接参加工作就在这里了。您是在这定居了还是工作在这儿？在这生活还习惯吗？ | F11: 在这定居了 | G11: 5 | H11: 外呼触点 | I11: 老板，您是做什么生意的？ | J11: 做建材的 | K11: 5
A12: 11 | B12: 场景1客户6 | C12: 个体工商户 | D12: 外呼触点 | E12: 老板，最近生意挺好的吧？ | F12: 还能凑乎 | G12: 5 | H12: 入户触点 | I12: 老板，最近生意怎么样呀？ | J12: 我这里生意倒是还可以 | K12: 5
A13: 12 | B13: 场景1客户6 | C13: 个体工商户 | D13: 外呼触点 | E13: 老板，您是做什么生意的？ | F13: 做建材的 | G13: 5 | H13: 入户触点 | I13: 这疫情过去了，感觉房地产行业回暖了好多，所以咱们这建材生意也挺好的。 | J13: 是呢，今年比前两年好做多了。 | K13: 5
... A17: 16 | B17: 场景2客户2 | C17: 个体工商户 | D17: 外呼触点 | E17: 老板，您是做什么生意的？ | F17: 做建材的 | G17: 5 | H17: 入户触点 | I17: 这疫情过去了，感觉房地产行业回暖了好多，所以咱们这建材生意也挺好的。 | J17: 是呢，今年比前两年好做多了。 | K17: 5
A18: 17 | B18: 场景2客户3 | C18: 抖音、快手偏好客户 | D18: 外呼触点 | E18: 您一般上网是追剧还是刷抖音和快手呢？ | F18: 是的，平时就爱刷刷抖音 | G18: 5 | H18: 进厅触点 | I18: 您一般上网是追剧还是刷抖音和快手呢？ | J18: 是的，平时就爱刷刷抖音 | K18: 5 | L18: 入户触点 | M18: 您一般上网是追剧还是刷抖音和快手呢？ | N18: 是的，平时就爱刷刷抖音 | O18: 5
A19: 18 | B19: 场景2客户3 | C19: 抖音、快手偏好客户 | D19: 外呼触点 | E19: 那我本次为您推荐的业务真的很适合你，我给您简单说一下。 | F19: 好的 | G19: 5 | H19: 进厅触点 | I19: 那我本次为您推荐的业务真的很适合你，我给您简单说一下。 | J19: 好的 | K19: 5 | L19: 入户触点 | M19: 那我本次为您推荐的业务真的很适合你，我给您简单说一下。 | N19: 好的 | O19: 5
A20: 19 | B20: 场景2客户4 | C20: 全职妈妈 | D20: 外呼触点 | E20: 看您这么年轻，没想到竟然都是俩个孩子的妈妈了。俩个宝宝都这么可爱！ | F20: 嘿嘿，谢谢夸奖，是俩个淘气鬼。 | G20: 5 | H20: 入户触点 | I20: 看您这么年轻，没想到竟然都是俩个孩子的妈妈了。俩个宝宝都这么可爱！ | J20: 嘿嘿，谢谢夸奖，是俩个淘气鬼。 | K20: 5
A21: 20 | B21: 场景2客户4 | C21: 全职妈妈 | D21: 外呼触点 | E21: 俩个宝宝长得跟您真像啊，有这么可爱小宝宝，真是让人羡慕啊！ | F21: 哈哈，您真会说话! | G21: 5 | H21: 入户触点 | I21: 俩个宝宝长得跟您真像啊，有这么可爱小宝宝，真是让人羡慕啊！ | J21: 哈哈，您真会说话! | K21: 5
A22: 21 | B22: 场景2客户5 | C22: 在校大学生 | D22: 外呼触点 | E22: 听你说话口音不是本地人吧，老家是哪里的呀?你是那个学校的？快毕业了吧？ | F22: 老家是东北的，我是农牧学校的，嗯，快了，现在在单位实习期 | G22: 5 | H22: 进厅触点 | I22: 你好，需要办理什么业务，看你好年轻啊，还在上学吧！ | J22: 嗯，还在上学，最近放假了 | K22: 5
A23: 22 | B23: 场景2客户5 | C23: 在校大学生 | D23: 外呼触点 | E23: 哦，太巧了，我妹妹也在你们学校。当时学校门口有个卖炸串的店是学生勤功俭学开的，现在还在吧？ | F23: 嗯，是的，味道不错 | G23: 5 | H23: 进厅触点 | I23: 哦，真好，有寒暑假，多出去转转看看 | J23: 嗯，过两天就出门。 | K23: 5
A24: 23 | B24: 场景2客户6 | C24: 务工人员 | D24: 外呼触点 | E24: 听您口音不想本地人，您是来这边工作的吗？ | F24: 是啊，找工作找到这边了。 | G24: 5 | H24: 进厅触点 | I24: 您是外地过来上班的啊，帮您看了一下语音和流量不太够用，是不是没有无线用的有点儿紧张 | J24: 是了哇，流量天天怕超了，打电话也得稍微注意着 | K24: 5 | L24: 入户触点 | M24: 您好，我是中国移动的客户经理，看您好年轻呀，已经上班了吗？ | N24: 是了，刚上班，租的房 | O24: 5
A25: 24 | B25: 场景2客户6 | C25: 务工人员 | D25: 外呼触点 | E25: 您在这边还习惯吧，我们这边早晚气温比较低~ | F25: 咱们这边可太舒服了，夏天也没有那么炎热。 | G25: 5 | H25: 进厅触点 | I25: 我们给你推荐的这个政策很合适您，您有需要的话可以办理，这样在家、在外面都不怕超了 | J25: 我考虑考虑 | K25: 5 | L25: 入户触点 | M25: 您好，我是中国移动的客户经理，您不是本地的啊，鄂尔多斯人文环境都挺好的，留下来不错。 | N25: 是的，来了感觉还不错 | O25: 5
A26: 25 | B26: 场景3客户1 | C26: 职场青年 | D26: 外呼触点 | E26: 您长的好年轻啊，你是学生还是工作了 | F26: 工作了 | G26: 5 | H26: 进厅触点 | I26: 看你好年轻啊，你还是学生吧 | J26: 不，已经工作了 | K26: 5
A27: 26 | B27: 场景3客户1 | C27: 职场青年 | D27: 外呼触点 | E27: 看您话费是有统付这些了，福利待遇挺好呀 | F27: 还行 | G27: 5 | H27: 进厅触点 | I27: 哦，看你套餐消费这么高，平时工作应该很忙。 | J27: 嗯，是的，工作比较忙 | K27: 5
A28: 27 | B28: 场景3客户2 | C28: 高龄独居老人 | D28: 进厅触点 | E28: 老人家，家里就您自己，您没跟孩子一起住啊？ | F28: 没有，年轻人跟我们生活习惯不一样，我就不去麻烦他们了，工作都忙。 | G28: 5 | H28: 入户触点 | I28: 您好，大爷，需要办理什么业务？ | J28: 我想查查话费 | K28: 5
A29: 28 | B29: 场景3客户2 | C29: 高龄独居老人 | D29: 进厅触点 | E29: 是吧，我母亲也是，自己在老家待着，也不愿意跟我们一起住。老人家，您今年贵庚啊？ | F29: 我今年75了。我们这个年纪，身子骨硬朗，不愿意麻烦你们年轻人。 | G29: 5 | H29: 入户触点 | I29: 好的，我帮您查查，话费不够用么？还是总是超套餐？ | J29: 是的，总是不够用 | K29: 5
A30: 29 | B30: 场景3客户3 | C30: 务工人员 | D30: 外呼触点 | E30: 听您口音不想本地人，您是来这边工作的吗？ | F30: 是啊，找工作找到这边了。 | G30: 5 | H30: 进厅触点 | I30: 您是外地过来上班的啊，帮您看了一下语音和流量不太够用，是不是没有无线用的有点儿紧张 | J30: 是了哇，流量天天怕超了，打电话也得稍微注意着 | K30: 5 | L30: 入户触点 | M30: 您好，我是中国移动的客户经理，看您好年轻呀，已经上班了吗？ | N30: 是了，刚上班，租的房 | O30: 5
A31: 30 | B31: 场景3客户3 | C31: 务工人员 | D31: 外呼触点 | E31: 您在这边还习惯吧，我们这边早晚气温比较低~ | F31: 咱们这边可太舒服了，夏天也没有那么炎热。 | G31: 5 | H31: 进厅触点 | I31: 我们给你推荐的这个政策很合适您，您有需要的话可以办理，这样在家、在外面都不怕超了 | J31: 我考虑考虑 | K31: 5 | L31: 入户触点 | M31: 您好，我是中国移动的客户经理，您不是本地的啊，鄂尔多斯人文环境都挺好的，留下来不错。 | N31: 是的，来了感觉还不错 | O31: 5
A32: 31 | B32: 场景3客户4 | C32: 商务人士 | D32: 外呼触点 | E32: 领导您工作是不是挺忙的呀，平时出差是不是比较多。 | F32: 嗯，平时工作比较多。 | G32: 5 | H32: 进厅触点 | I32: 领导您工作是不是挺忙的呀，平时出差是不是比较多。 | J32: 嗯，平时工作比较多。 | K32: 5
A33: 32 | B33: 场景3客户4 | C33: 商务人士 | D33: 外呼触点 | E33: 那挺辛苦的，那我简短点给您介绍。 | F33: 好的 | G33: 5 | H33: 进厅触点 | I33: 那挺辛苦的，那我简短点给您介绍。 | J33: 好的 | K33: 5
A34: 33 | B34: 场景3客户5 | C34: 高龄独居老人 | D34: 进厅触点 | E34: 老人家，家里就您自己，您没跟孩子一起住啊？ | F34: 没有，年轻人跟我们生活习惯不一样，我就不去麻烦他们了，工作都忙。 | G34: 5 | H34: 入户触点 | I34: 您好，大爷，需要办理什么业务？ | J34: 我想查查话费 | K34: 5
A35: 34 | B35: 场景3客户5 | C35: 高龄独居老人 | D35: 进厅触点 | E35: 是吧，我母亲也是，自己在老家待着，也不愿意跟我们一起住。老人家，您今年贵庚啊？ | F35: 我今年75了。我们这个年纪，身子骨硬朗，不愿意麻烦你们年轻人。 | G35: 5 | H35: 入户触点 | I35: 好的，我帮您查查，话费不够用么？还是总是超套餐？ | J35: 是的，总是不够用 | K35: 5
A36: 35 | B36: 场景3客户6 | C36: 高中毕业生 | D36: 进厅触点 | E36: 您现在是还在上高中吗？听你声音好年轻啊。 | F36: 我6月份就毕业了。 | G36: 5 | H36: 入户触点 | I36: 您现在是还在上高中吗？看你好年轻啊。 | J36: 我6月份就毕业了。 | K36: 5
A37: 36 | B37: 场景3客户6 | C37: 高中毕业生 | D37: 进厅触点 | E37: 那提前预祝你取得好成绩，上个心仪的好大学！ | F37: 谢谢 | G37: 5 | H37: 入户触点 | I37: 那提前预祝你取得好成绩，上个心仪的好大学！ | J37: 谢谢 | K37: 5
A38: 37 | B38: 场景4客户1 | C38: 高龄独居老人 | D38: 进厅触点 | E38: 老人家，家里就您自己，您没跟孩子一起住啊？ | F38: 没有，年轻人跟我们生活习惯不一样，我就不去麻烦他们了，工作都忙。 | G38: 5 | H38: 入户触点 | I38: 您好，大爷，需要办理什么业务？ | J38: 我想查查话费 | K38: 5
A39: 38 | B39: 场景4客户1 | C39: 高龄独居老人 | D39: 进厅触点 | E39: 是吧，我母亲也是，自己在老家待着，也不愿意跟我们一起住。老人家，您今年贵庚啊？ | F39: 我今年75了。我们这个年纪，身子骨硬朗，不愿意麻烦你们年轻人。 | G39: 5 | H39: 入户触点 | I39: 好的，我帮您查查，话费不够用么？还是总是超套餐？ | J39: 是的，总是不够用 | K39: 5
A40: 39 | B40: 场景4客户2 | C40: 个体工商户 | D40: 外呼触点 | E40: 老板，最近生意挺好的吧？ | F40: 还能凑乎 | G40: 5 | H40: 入户触点 | I40: 老板，最近生意怎么样呀？ | J40: 我这里生意倒是还可以 | K40: 5
A41: 40 | B41: 场景4客户2 | C41: 个体工商户 | D41: 外呼触点 | E41: 老板，您是做什么生意的？ | F41: 做建材的 | G41: 5 | H41: 入户触点 | I41: 这疫情过去了，感觉房地产行业回暖了好多，所以咱们这建材生意也挺好的。 | J41: 是呢，今年比前两年好做多了。 | K41: 5
A42: 41 | B42: 场景4客户3 | C42: 在校大学生 | D42: 外呼触点 | E42: 听你说话口音不是本地人吧，老家是哪里的呀?你是那个学校的？快毕业了吧？ | F42: 老家是东北的，我是农牧学校的，嗯，快了，现在在单位实习期 | G42: 5 | H42: 进厅触点 | I42: 你好，需要办理什么业务，看你好年轻啊，还在上学吧！ | J42: 嗯，还在上学，最近放假了 | K42: 5
A43: 42 | B43: 场景4客户3 | C43: 在校大学生 | D43: 外呼触点 | E43: 哦，太巧了，我妹妹也在你们学校。当时学校门口有个卖炸串的店是学生勤功俭学开的，现在还在吧？ | F43: 嗯，是的，味道不错 | G43: 5 | H43: 进厅触点 | I43: 哦，真好，有寒暑假，多出去转转看看 | J43: 嗯，过两天就出门。 | K43: 5
...

Sheet 销售对话池
A1: 排序 | B1: 产品名称 | C1: 内容11 | D1: 回复11 | E1: 得分11 | F1: 内容12 | G1: 回复12 | H1: 得分12 | I1: 内容21 | J1: 回复21 | K1: 得分21 | L1: 内容22 | M1: 回复22 | N1: 得分22 | O1: 内容31 | P1: 回复31 | Q1: 得分31 | R1: 内容32 | S1: 回复32 | T1: 得分32
A2: 1 | B2: 前三月1元15G定向流量包（抖音） | C2: 我们针对向您这种的优质客户专门申请了前三月1元包含15GB的抖音定向流量包，第四个月恢复原价9元/月，您可以先体验几个月，如您感觉产品不错您就继续使用，如您不想使用了可以随时联系我帮您办理，您看您是体验抖音包还是快手包啊？ | D2: 抖音包吧，一般看抖音看的比较多 | E2: 5 | F2: 您一般是看抖音多还是快手多呢？我们推出了前三月1元包含15GB的抖音或者快手的定向流量包，第四个月恢复原价9元/月，您看需要为您办理吗？ | G2: 抖音包吧，一般看抖音看的比较多 | H2: 4 | I2: 我们这个定向流量特惠包真的是很优惠呢，尤其咱们现在免不了刷刷抖音快手，前3个月才1元，合计每GB才6分钱，这么优惠的流量包现在可少了 | J2: 这样算下来确实挺优惠 | K2: 5 | L2: 我们这个定向流量前3个月1元，第4个月起正价9元，基本能满足您刷抖音快手的需求。 | M2: 价格还算优惠 | N2: 4 | O2: 咱们这个流量包您想看视频随意刷，就是不包含直播的，我现在帮您订购一下吧？ | P2: 好的 | Q2: 5 | R2: 这么优惠的包，您考虑办一个吗？ | S2: 我再考虑考虑 | T2: 4
A3: 2 | B3: 前三月1元15G定向流量包（快手） | C3: 我们针对向您这种的优质客户专门申请了前三月1元包含15GB的抖音/快手定向流量包，第四个月恢复原价9元/月，您可以先体验几个月，如您感觉产品不错您就继续使用，如您不想使用了可以随时联系我帮您办理，您看您是体验抖音包还是快手包啊？ | D3: 快手包吧，一般看快手看的比较多 | E3: 5 | F3: 您一般是看抖音多还是快手多呢？我们推出了前三月1元包含15GB的抖音或者快手的定向流量包，第四个月恢复原价9元/月，您看需要为您办理吗？ | G3: 快手包吧，一般看快手看的比较多 | H3: 4 | I3: 我们这个定向流量特惠包真的是很优惠呢，尤其咱们现在免不了刷刷抖音快手，前3个月才1元，合计每GB才6分钱，这么优惠的流量包现在可少了 | J3: 这样算下来确实挺优惠 | K3: 5 | L3: 我们这个定向流量前3个月1元，第4个月起正价9元，基本能满足您刷抖音快手的需求。 | M3: 价格还算优惠 | N3: 4 | O3: 咱们这个流量包您想看视频随意刷，就是不包含直播的，我现在帮您订购一下吧？ | P3: 好的 | Q3: 5 | R3: 这么优惠的包，您考虑办一个吗？ | S3: 我再考虑考虑 | T3: 4
A4: 3 | B4: 前三月1元30G定向流量包（抖音） | C4: 我们针对向您这种的优质客户专门申请了前三月1元包含30GB的抖音/快手定向流量包，第四个月恢复原价19元/月，您可以先体验几个月，如您感觉产品不错您就继续使用，如您不想使用了可以随时联系我帮您办理，您看您是体验抖音包还是快手包啊？ | D4: 抖音包吧，一般看抖音看的比较多 | E4: 5 | F4: 您一般是看抖音多还是快手多呢？我们推出了前三月1元包含30GB的抖音或者快手的定向流量包，第四个月恢复原价19元/月，您看需要为您办理吗？ | G4: 抖音包吧，一般看抖音看的比较多 | H4: 4 | I4: 我们这个定向流量特惠包真的是很优惠呢，尤其咱们现在免不了刷刷抖音快手，前3个月才1元，合计每GB才3分钱，这么优惠的流量包现在可少了 | J4: 这样算下来确实挺优惠 | K4: 5 | L4: 我们这个定向流量前3个月1元，第4个月起正价9元，基本能满足您刷抖音快手的需求。 | M4: 价格还算优惠 | N4: 4 | O4: 咱们这个流量包您想看视频随意刷，就是不包含直播的，我现在帮您订购一下吧？ | P4: 好的 | Q4: 5 | R4: 这么优惠的包，您考虑办一个吗？ | S4: 我再考虑考虑 | T4: 4
A5: 4 | B5: 前三月1元30G定向流量包（快手） | C5: 我们针对向您这种的优质客户专门申请了前三月1元包含30GB的抖音/快手定向流量包，第四个月恢复原价19元/月，您可以先体验几个月，如您感觉产品不错您就继续使用，如您不想使用了可以随时联系我帮您办理，您看您是体验抖音包还是快手包啊？ | D5: 快手包吧，一般看快手看的比较多 | E5: 5 | F5: 您一般是看抖音多还是快手多呢？我们推出了前三月1元包含30GB的抖音或者快手的定向流量包，第四个月恢复原价19元/月，您看需要为您办理吗？ | G5: 快手包吧，一般看快手看的比较多 | H5: 4 | I5: 我们这个定向流量特惠包真的是很优惠呢，尤其咱们现在免不了刷刷抖音快手，前3个月才1元，合计每GB才3分钱，这么优惠的流量包现在可少了 | J5: 这样算下来确实挺优惠 | K5: 5 | L5: 我们这个定向流量前3个月1元，第4个月起正价9元，基本能满足您刷抖音快手的需求。 | M5: 价格还算优惠 | N5: 4 | O5: 咱们这个流量包您想看视频随意刷，就是不包含直播的，我现在帮您订购一下吧？ | P5: 好的 | Q5: 5 | R5: 这么优惠的包，您考虑办一个吗？ | S5: 我再考虑考虑 | T5: 4
A6: 8 | B6: 150元240GB抖音+快手流量年包-鄂尔多斯 | C6: 我们针对优质客户推出了一个流量年包活动，每月不到13元，1年内能有240GB的流量，其中还有15G的通用流量，剩余的225G可随意刷抖音和快手。 | D6: 好的，那你给我办理吧 | E6: 5 | F6: 我们现在推出了一个流量年包活动，150元包含240GB的流量，其中15G的通用流量，剩余的225G为抖音、快手定向流量。 | G6: 好的，那你给我办理吧 | H6: 4 | I6: 您看现在的抖音、快手流量包是19元/月30GB的流量，而且只能选择一个APP使用，如果您两个APP都想使用，需要开通两个产品包，这样算下来就需要花费38元/月了，咱们的这个产品包抖音和快手可以同时使用的，是不是划算多了。 | J6: 这样算下来确实挺优惠 | K6: 5 | L6: 您看现在的抖音、快手流量包是19元/月30GB的流量，一年就需要228元了 | M6: 确实挺贵 | N6: 4 | O6: 这样一算挺优惠吧，那我现在帮您订购一下吧？ | P6: 好的 | Q6: 5 | R6: 这么优惠的包，您考虑办一个吗？ | S6: 我再考虑考虑
A7: 9 | B7: 200元360GB抖音+快手流量年包-鄂尔多斯 | C7: 我们针对优质客户推出了一个流量年包活动，每月不到17元，1年内能有360GB的流量，其中还有20G的通用流量，剩余的340G可随意刷抖音和快手， | D7: 好的，那你给我办理吧 | E7: 5 | F7: 我们现在推出了一个流量年包活动，200元包含360GB的流量，其中20G的通用流量，剩余的340G为抖音、快手定向流量。 | G7: 好的，那你给我办理吧 | H7: 4 | I7: 您看现在的抖音、快手流量包是19元/月30GB的流量，而且只能选择一个APP使用，如果您两个APP都想使用，需要开通两个产品包，这样算下来就需要花费38元/月了，咱们的这个产品包抖音和快手可以同时使用的，是不是划算多了。 | J7: 这样算下来确实挺优惠 | K7: 5 | L7: 您看现在的抖音、快手流量包是19元/月30GB的流量，一年就需要228元了 | M7: 确实挺贵 | N7: 4 | O7: 这样一算挺优惠吧，那我现在帮您订购一下吧？ | P7: 好的 | Q7: 5 | R7: 这么优惠的包，您考虑办一个吗？ | S7: 我再考虑考虑
A8: 10 | B8: 3元20GB农村区域流量包-鄂尔多斯 | C8: 我们针对农村客户推出了一个特别优惠的活动，根据您每月消费金额，可以办理一个3元20GB的区域流量包。 | D8: 挺多流量呀 | E8: 5 | F8: 根据您的消费，您套餐升档就可以参加3元20GB 的区域流量活动。 | G8: 好的 | H8: 4 | I8: 这个只针对目标客户开展呢，均下来每GB才1毛5，特别优惠了呢。 | J8: 这样算下来确实挺优惠 | K8: 5 | L8: 这个流量包确实比较优惠的，而且只针对农村客户办理 | M8: 好的 | N8: 4 | O8: 这样一算挺优惠吧，那我现在帮您订购一下吧？ | P8: 好的 | Q8: 5 | R8: 这么优惠的包，您考虑办一个吗？ | S8: 我再考虑考虑
A9: 11 | B9: 1元30GB农村区域流量包-鄂尔多斯 | C9: 我们针对农村客户推出了一个特别优惠的活动，您现在每月消费40元左右，套餐有12GB的流量，现在每月仅需39元就能有42GB流量，比您之前多30GB流量。 | D9: 挺多流量呀 | E9: 5 | F9: 我们现在推出了一个每月39元，有42GB流量，和200分钟的套餐。 | G9: 好的 | H9: 4 | I9: 这个只针对目标客户开展呢，算下来流量比您原来的套餐多了不少，现在可以放放心心的刷视频上网了 | J9: 这样算下来确实挺优惠 | K9: 5 | L9: 这个流量包确实比较优惠的，而且只针对目标客户办理 | M9: 好的 | N9: 4 | O9: 这样一算挺优惠吧，那我现在帮您订购一下吧？ | P9: 好的 | Q9: 5 | R9: 这么优惠的包，您考虑办一个吗？ | S9: 我再考虑考虑
A10: 12 | B10: 1元50GB农村区域流量包-鄂尔多斯 | C10: 我们针对农村客户推出了一个特别优惠的活动，您现在每月消费60元左右，套餐有20GB的流量，现在每月仅需59元就能有70GB流量，比您之前多50GB流量。 | D10: 挺多流量呀 | E10: 5 | F10: 我们现在推出了一个每月59元，有70GB流量，和200分钟的套餐。 | G10: 好的 | H10: 4 | I10: 这个只针对目标客户开展呢，算下来流量比您原来的套餐多了不少，现在可以放放心心的刷视频上网了 | J10: 这样算下来确实挺优惠 | K10: 5 | L10: 这个流量包确实比较优惠的，而且只针对目标客户办理 | M10: 好的 | N10: 4 | O10: 这样一算挺优惠吧，那我现在帮您订购一下吧？ | P10: 好的 | Q10: 5 | R10: 这么优惠的包，您考虑办一个吗？ | S10: 我再考虑考虑
A11: 13 | B11: 1元70GB农村区域流量包-鄂尔多斯 | C11: 我们针对农村客户推出了一个特别优惠的活动，您现在每月消费80元左右，套餐有20GB的流量，现在每月仅需80元就能有90GB流量，比您之前多70GB流量。 | D11: 挺多流量呀 | E11: 5 | F11: 我们现在推出了一个每月80元，有90GB流量，和200分钟的套餐。 | G11: 好的 | H11: 4 | I11: 这个只针对目标客户开展呢，算下来流量比您原来的套餐多了不少，现在可以放放心心的刷视频上网了 | J11: 这样算下来确实挺优惠 | K11: 5 | L11: 这个流量包确实比较优惠的，而且只针对目标客户办理 | M11: 好的 | N11: 4 | O11: 这样一算挺优惠吧，那我现在帮您订购一下吧？ | P11: 好的 | Q11: 5 | R11: 这么优惠的包，您考虑办一个吗？ | S11: 我再考虑考虑
A12: 22 | B12: 29元归位包 | C12: 根据您最近的消费情况，中国移动特为您申请到优惠政策，无需变更套餐，每月仅需29元，即可在套餐外多享受40GB流量，其中20GB全国流量和20GB鄂尔多斯流量；还有200分钟语音通话并且还会赠送您权益超市会员和咪咕视频会员还有10GB的咪咕视频定向流量。 | D12: 不用了，谢谢 | E12: 5 | F12: 作为移动的老用户，现为您申请了一个政策，每月40GB流量，其中20GB为鄂尔多斯本地流量，同时赠送您200分钟语音和权益超市会员和咪咕视频会员与流量。办理该活动，您无需变更套餐，每个月仅29元。 | G12: 不用了，谢谢 | H12: 4 | I12: 您要不可以先办理一个月试试看，一月后如果不满意您再联系我更改，因为这个政策内包含的流量语音是比正常套餐要优惠的多的。 | J12: 好的，那你给我办理吧 | K12: 5 | L12: 我们查询到您现在套餐内的资源较少，使用过程中容易有超套行为，您订购这个政策后，每月仅需多花费29元钱，享受到的内容是要比所有套餐内的都合适的，您不妨把你后试试，如果合适您也可以办他网的资费下调一些，这样算下来可能还会少花点钱。 | M12: 好的，那你给我办理吧 | N12: 4 | O12: 好的，那我现在为您办理，办理后立即生效，有效期12个月，到期后我们会联系您看是否需要继续续约办理。 | P12: 好的 | Q12: 5
A13: 23 | B13: 39元归位包 | C13: 根据您最近的消费情况，中国移动特为您申请到优惠政策，无需变更套餐，每月仅需39元，即可在套餐外多享受100GB流量，其中30GB全国流量和70GB鄂尔多斯流量；还有600分钟语音通话并且还赠送您权益超市会员和咪咕视频会员还有10GB的咪咕视频定向流量。 | D13: 不用了，谢谢 | E13: 5 | F13: 作为移动的老用户，现为您申请了一个优惠政策，每月100GB流量，其中70GB为鄂尔多斯本地流量，同时赠送您600分钟语音和权益超市会员和咪咕视频会员与流量。办理该活动，您无需变更套餐，每个月仅39元。 | G13: 不用了，谢谢 | H13: 4 | I13: 您要不可以先办理一个月试试看，一月后如果不满意您再联系我更改，因为这个政策内包含的流量语音是比正常套餐要优惠的多的。 | J13: 好的，那你给我办理吧 | K13: 5 | L13: 我们查询到您现在套餐内的资源较少，使用过程中容易有超套行为，您订购这个政策后，每月仅需多花费39元钱，享受到的内容是要比所有套餐内的都合适的，您不妨把你后试试，如果合适您也可以办他网的资费下调一些，这样算下来可能还会少花点钱。 | M13: 好的，那你给我办理吧 | N13: 4 | O13: 好的，那我现在为您办理，办理后立即生效，有效期12个月，到期后我们会联系您看是否需要继续续约办理。 | P13: 好的 | Q13: 5
A14: 24 | B14: 5G特色视频彩铃包 | C14: 视频彩铃支持个性化DIY制作，可根据自己的喜好个性化设置，个性化制作视频。还有一个功能是可以实现视频里的人物AI换脸。根据相关法律、法规及用户协议规定，个性化上传的视频内容需要按照要求严格审核，通过后可以成功设置彩铃。 | D14: 好的 | E14: 5 | F14: 中国移动推出的视频彩铃，订购后，当别人给你打电话时，可以观看一段您设置的视频，每月6月，可以在咪咕音乐APP彩铃专区下载设置，热门精品视频可以做自己的手机彩铃，不限下载次数，让个性看的见。也可以使用自己的照片，DIY制作个性化的手机彩铃。 | G14: 好的 | H14: 4 | I14: 中国移动推出视频彩铃业务是可观看的有声音有画面的短视频内容，而音频彩铃，只能挺到声音，看不到图像。 | J14: 是的 | K14: 5 | L14: 中国移动推出视频彩铃业务是可观看的有声音有画面的短视频内容，而音频彩铃，只能挺到声音，看不到图像。 | M14: 好的 | N14: 4 | O14: 视频彩铃支持个性化DIY制作，制作流程很简单，只要选择好照片，套用免费的炫酷模板，合成后一条精致的短视频就做好了，很有成就感，可以设置指定的彩铃可见人员，记录分享生活的幸福，感动的瞬间。每月只要5元，还包含1GB通用流量。还您可以亲自体验感受下，我帮您下载咪咕音乐APP就可以开始制作了。 | P14: 好的，谢谢 | Q14: 5 | R14: 视频彩铃设置及制作流程都很简单，只要选择好照片，套用免费的AI创作模板，轻松实现人物AI换脸，很好玩。记录分享生活的幸福，感动的瞬间，设置指定的彩铃可见人员。每月只要3元，您可以亲自体验感受下，我帮您下载咪咕音乐APP就可以开始制作了。 | S14: 好的 | T14: 4
A15: 25 | B15: 3元商户彩铃包 | C15: 中国移动推出的视频彩铃不仅可以自己定制个性化的彩铃内容，并且可指定彩铃可见人员。而且也可以为宣传企业文化及活动，省去单位大额的广告投入，降本增效。 | D15: 好的 | E15: 5 | F15: 这个是我们针对十大行业制作好的彩铃内容模板，主要有党政机关服务类、文旅类、教育、餐饮、健身、医药行业、快递行业、个体工商户等服务类的彩铃。可以免费提供给客户使用，也可以根据咱们个性化的需求免费制作，满足个性化宣传需求。 | G15: 好的 | H15: 4 | I15: 中国移动推出视频彩铃业务是可观看的有声音有画面的短视频内容，而音频彩铃，只能挺到声音，看不到图像。 | J15: 是的 | K15: 5 | L15: 中国移动推出视频彩铃业务是可观看的有声音有画面的短视频内容，而音频彩铃，只能挺到声音，看不到图像。 | M15: 好的 | N15: 4 | O15: 咱们这次免费制作彩铃的活动力度挺大的，我们有专业制作短视频的团队帮您免费制作，也省去了您花钱找广告公司制作的成本费用，而且也不用签订各种合同，短期长期使用都很灵活，您单位某个月有活动需要宣传预热下，咱们就用一个月，关键是投入的成本少。你看就是这种效果（出示行业彩铃模板演示），您可以先开通体验下，可以吗？ | P15: 好的，谢谢 | Q15: 5 | R15: 只要咱们公司内部员工开通视频彩铃功能业务，由移动公司为您免费制作短视频，免费承载到咱们官方的咪咕音乐APP上，设置成功后，客户给您单位员工打电话的时候，客户就能看到单位宣传内容，简单实现线上宣传。你看就是这种效果（出示行业彩铃模板演示），可以为您简单介绍下可以吗？ | S15: 好的 | T15: 4
A16: 26 | B16: 移动云盘白银会员(连续包月) | C16: 中国移动云盘是一款非常便捷的办公软件，可以帮助我们提高工作效率，比如公司开会要出会议纪要可以使用语音笔记速转文字功能；下班不用带电脑，使用同步盘手机上也能下载转发文件。组建共享群组，高效收发共享文件等等非常实用。还有就是PDF文档格式互转。其实中国移动网盘一点都不贵，功能这么强大，白银会员10元/月，每天只花3毛钱，就能解决工作中很多琐碎的事情。 | D16: 好的，确实厅实用的 | E16: 5 | F16: 中国移动云盘的存储空间特别大，有5TB。白银会员包含个人空间3TB+家庭空间2TB。家庭成员也可以随时随地分享照片、视频、文件到云盘。您不用担心手机空间不够用删掉宝贵的照片了。白银会员10元/月，其实中国移动网盘一点都不贵，相当于您手机自带的网盘一天才花3毛钱。 | G16: 好的 | H16: 4 | I16: 从安全性来看，和同类型网盘软件对比，中国移动云盘目前市面上安全性最高的存储软件。价格方面：咱们白银会员年包产品每年120元，价格是很亲民的，和同类型其他网盘比较一年要298元。 | J16: 嗯，挺好的，我用的是别的网盘 | K16: 5 | L16: 现在信息安全这么重要，咱们工作中的重要文件、资料都可以储存、备份在中国移动云盘上，和同类型网盘软件对比中国移动云盘目前市面上安全性最高的存储软件。 | M16: 嗯，数据安全性很重要。 | N16: 4 | O16: 现在大家都比较关注信息安全了，都不希望自己的信息被泄露。目前很多客户反映自己用的云空间比较贵，非会员下载速率超级慢，卡顿现象。您有使用云空间的习惯吗？咱们工作中的重要文件、资料都可以储存、备份在中国移动云盘上，永不丢失。如果出差或者不在单位的时候，领导或者同事着急要文件，单位电脑转文件超级不方便的。中国移动云盘可以帮您实现电脑文件同步到手机上，上传下载文件都不限速，还免流不占用您套餐流量，随时随地查看转发文件给领导，不耽误工作。我帮您演示下，价格亲民，每天只要3毛，您也可以亲自体验感受下，可以吗？ | P16: 好的，帮我开通了 | Q16: 5 | R16: 咱们平时工作中在微信上的文件、图片、大视频经常占用手机空间，手机存储总是不够用，您看中国移动云盘APP上可以设置文件一键备份功能，轻松帮您释放手机空间。更重要的是咱们数据安全性高呀，最近中国移动云盘APP上还有个活动，每周都可以免费领取1GB通用流量，顺便告诉你在哪里领，您可以领取下。您扫一下这个二维码，我来帮您设置好自动备份，这样你就不用手动一个个存照片了！ | S16: 好的。 | T16: 4
A17: 27 | B17: 黑卡PLUS会员 | C17: 我们公司现在有个优惠产品每月1.9元，可享受部分超市购物95折起，餐饮甜品等优惠75折起优惠权益，订购后可立即回本。 | D17: 不用了，谢谢 | E17: 5 | F17: 我们移动公司有一款权益会员，每月仅需1.9元，您是否可以了解一下？ | G17: 先不用了，谢谢 | H17: 4 | I17: 黑卡会员和咱们鄂尔多斯的吃货热榜相比较，吃货热榜的商户较多，我们的权益商户较少，但是我们的商户比较集中，优惠力度大于吃货热榜的优惠力度，例如：吃货热榜会员在乐和小厨的优惠折扣是9.1折，我们黑卡会员的优惠折扣是8.7折。 | J17: 好的 | K17: 5 | L17: 咱们黑卡会员您在商超还有指定餐饮消费的时候是可以享受打折优惠的，并且每个月才1.9元。 | M17: 好的，那你给我办理吧 | N17: 4 | O17: 那我现在为您办理，办理后立即生效。 | P17: 好的 | Q17: 5
A18: 28 | B18: 生态随心选会员5元 | C18: 我们推出一款特别合适的产品，您方便了解一下吗? 包含黑卡会员、3元超市优惠券，还有2GB流量。 | D18: 我再等等办理吧，我应该用不到这么高套餐 | E18: 5 | F18: 我们的随心选产品包含权益较丰富，可享受黑卡会员、加油、电费、互联网流量等多种权益。 | G18: 先不用了，谢谢 | H18: 4 | I18: 您在使用移动业务的过程中遇到任何问题都可以帮您解决处理。 | J18: 好的 | K18: 5 | L18: 这是我的名片，你们这的客流量还挺大的，生意不错呀，你们店是不是搞活动呢?您也可以和我们联合做活动。 | M18: 好的，让我们考虑考虑 | N18: 4 | O18: 那我现在为您办理，办理后立即生效。 | P18: 好的 | Q18: 5
A19: 29 | B19: 生态随心选会员10元 | C19: 我查了一下，为您办理后，您可享受权益超市黄金会员、黑卡会员、10元生态券（每月可领1次）、3GB通用流量+10GB定向流量多种优惠。 | D19: 需要升级套餐吗？ | E19: 5 | F19: 现在有一档适合您的资费，每月59元即可享受80GB通用流量，300分钟通话和100条短信，比你现有资费要优惠多了，并且还会额外赠送您其他权益内容。 | G19: 哦哦，我再想想吧 | H19: 4 | I19: 了解到您喜欢追剧，您经常喜欢通过爱奇艺、优酷、腾讯哪个APP追剧呢？ | J19: 好的 | K19: 5 | L19: 每月仅需10元，即可享受黑卡会员、加油立减10元、交电费立减10元、10GB爱优腾等互联网流量，您看是否要办理一下？ | M19: 好的，那你给我办理吧 | N19: 4 | O19: 那我现在为您办理，办理后立即生效。 | P19: 好的 | Q19: 5
A20: 30 | B20: 生态随心选会员20元 | C20: 了解到您本月多次在***店加油，请问结账过程中您是否享受了加油优惠？我查了一下，为您办理套餐后，您每月可享受20元加油优惠券（每月可领1次）。 | D20: 每月可以领一次？ | E20: 5 | F20: 每月59元即可享受80GB通用流量，300分钟通话和100条短信，比你现有资费要优惠多了，并且还会额外赠送您初加油券以外的其他权益内容。 | G20: 我再等等办理吧，我应该用不到这么高套餐 | H20: 4 | I20: 您现在每月可免费享受互联网权益会员打折优惠优惠、15GB流量，会员购物结算享受打折优惠等，你看是否办理一下？ | J20: 好的 | K20: 5 | L20: 得向您说明一下，办理订购后，每月会从您的移动话费中扣除20元，但会赠送您一张20元的超市无门槛的消费券，购物结算时，先享受会员扣，再使用消费券立减20元，您有什么疑问吗？ | M20: 好的，那你给我办理吧 | N20: 4 | O20: 那我现在为您办理，办理后立即生效。 | P20: 好的 | Q20: 5
A21: 31 | B21: 动感地带潮玩卡资费-39元 | C21: 中国移动特地为大学生申请到优惠政策，每月仅需39元，即可在普通套餐外多享受34GB全国流量和100条短信，还会额外赠送您咪咕三项会员权益（视频、音乐、游戏），和彩云，权益超市黄金会员。 | D21: 流量挺多的 | E21: 5 | F21: 您现在符合我们为大学生申请的一项政策，每月仅需39元，即可在享受200分钟语音+40GB通用流量+100条短信，并且还会额外赠送您咪咕三项会员权益（视频、音乐、游戏），和彩云，权益超市黄金会员， | G21: 哦哦 | H21: 4 | I21: 这个活动仅针对大学生开展，您刚好符合条件可以参加，办理新入网号码的就可以使用了，比您之前的套餐要多34G的流量，你现在没有宽带使用，很容易上网导致流量超出套内流量，套外5元/G流量，容易额外收取更多费用，根据您近几月流量使用情况这个套餐就够用了，如果不需要的话后期也可以随时销户。 | J21: 挺划算的 | K21: 5 | L21: 这个资费比您现在用的流量多34G ，还能享受咪咕的三项权益，你和家里人组个家庭网还可以免费互相通话，挺划算的。 | M21: 行吧 | N21: 4 | O21: 好的，那我现在为您办理，办理后您的资费是立即生效，活动也于立即生效，基础套餐月使用费按天折算收取，套餐内包含内容按天折算提供，按日计费进行扣费，到期后我们会再与您联系。 | P21: 好的 | Q21: 5
A22: 32 | B22: 动感地带潮玩卡资费-59元 | C22: 中国移动特地为大学生申请到优惠政策，每月仅需59元，即可在享受80GB全国流量和100条短信、300分钟通话。并且还会额外赠送您咪咕三项会员权益（视频、音乐、游戏），和彩云，权益超市黄金会员，全国家庭网。有需要的话还能办理校园宽带。 | D22: 我再等等办理吧，我应该用不到这么高套餐 | E22: 5 | F22: 现在有一档适合您的资费，每月59元即可享受80GB通用流量，300分钟通话和100条短信，比你现有资费要优惠多了，并且还会额外赠送您其他权益内容。 | G22: 我再等等办理吧，我应该用不到这么高套餐 | H22: 4 | I22: 咱们这个资费只有新入网的大学生才能办理呢，您办理咱妈这个资费就不用担心超套产生费用了，您现在学习资料这些上传留存还可以享受一下移动云盘业务，您有需求我可以为您办理。 | J22: 好的，那你给我办理吧 | K22: 5 | L22: 还会额外赠送您咪咕三项会员权益（视频、音乐、游戏），和彩云，权益超级黄金会员，全国家庭网。套餐所含内容丰富，赠送权益多，很划算的。 | M22: 好的，那你给我办理吧 | N22: 4 | O22: 好的，那我现在为您办理，办理后您的资费是立即生效，活动也于立即生效，基础套餐月使用费按天折算收取，套餐内包含内容按天折算提供，按日计费进行扣费，到期后我们会再与您联系。 | P22: 好的 | Q22: 5
A23: 33 | B23: 79元资费月返23元金币活动（24个月） | C23: 您现在购买手机终端且变更79元资费，可参加月返23元话费活动，也就是您每月花费56元即可享受到20GB流量和300分钟语音，语音和流量对比之前都有增加。 | D23: 我再等等办理吧，我应该用不到这么高套餐 | E23: 5 | F23: 您只要购买手机终端，可以为您申请的是79元资费，包含20GB流量，300分钟语音，并且为您申请了优惠，您办理后，每月为您返还23元话费，您每月只需花费56元。 | G23: 我再等等办理吧，我应该用不到这么高套餐 | H23: 4 | I23: 为您申请的政策是根据您近期消费及流量使用情况制定的，我们查询到您近期每个月流量使用都在20GB左右，消费都在50多块钱，您每个月只需多花费不到十块钱并且购买手机终端就可以享受以上优惠。 | J23: 好的，那你给我办理吧 | K23: 5 | L23: 我们查询到您近期的套内流量基本不够用，您在办理手机终端和申请的政策后，仅需多花几块钱就可以多享受20GB流量，这样您的其他卡就可以将资费便宜一些也够您用，这样算下来反而比您现在的总花费更少了。 | M23: 好的，那你给我办理吧 | N23: 4 | O23: 好的，那我现在为您办理，办理后您的资费是下周期1号生效，活动也于下周期1号生效，为您赠送的话费会在下月起每月底前直接返还到您的账户上，活动有效期24个月，到期后我们会再与您联系。 | P23: 好的，那你给我办理吧 | Q23: 5
A24: 34 | B24: 159元资费月返47元金币活动（24个月） | C24: 您现在购买手机终端且变更159元资费，可参加月返47元话费活动，也就是您每月花费112元即可享受到40GB流量和700分钟语音，语音和流量对比之前都有增加。 | D24: 我再等等办理吧，我应该用不到这么高套餐 | E24: 5 | F24: 您只要购买手机终端，可以为您申请的是159元资费，包含40GB流量，700分钟语音，并且为您申请了优惠，您办理后，每月为您返还47元话费，您每月只需花费112元。 | G24: 我再等等办理吧，我应该用不到这么高套餐 | H24: 4 | I24: 为您申请的政策是根据您近期消费及流量使用情况制定的，我们查询到您近期每个月流量使用都在40GB左右，消费都在100多块钱，您每个月只需多花费不到二十块钱并且购买手机终端就可以享受以上优惠。 | J24: 好的，那你给我办理吧 | K24: 5 | L24: 我们查询到您近期的套内流量基本不够用，您在办理手机终端和申请的政策后，仅需多花几块钱就可以多享受40GB流量，这样您的其他卡就可以将资费便宜一些也够您用，这样算下来反而比您现在的总花费更少了。 | M24: 好的，那你给我办理吧 | N24: 4 | O24: 好的，那我现在为您办理，办理后您的资费是下周期1号生效，活动也于下周期1号生效，为您赠送的话费会在下月起每月底前直接返还到您的账户上，活动有效期24个月，到期后我们会再与您联系。 | P24: 好的，那你给我办理吧 | Q24: 5
A25: 35 | B25: 58元资费月返17元话费金币活动（24个月） | C25: 为您申请的是58元资费，包含20GB流量，300分钟语音，并且为您申请了优惠，您办理后，每月为您返还17元话费，您每月只需花费41元。 | D25: 我再等等办理吧，我应该用不到这么高套餐 | E25: 5 | F25: 您现在变更58元资费，可参加月返17元话费活动，优惠完您每个月41元就可以享受原本58元的内容。 | G25: 我再等等办理吧，我应该用不到这么高套餐 | H25: 4 | I25: 我们查询到您近期的套内流量基本不够用，您在办理了申请的政策后，仅需多花几块钱就可以多享受20GB流量，这样您的其他卡就可以将资费便宜一些也够您用，这样算下来反而比您现在的总花费更少了。 | J25: 好的，那你给我办理吧 | K25: 5 | L25: 为您申请的政策是根据您近期消费及流量使用情况制定的，我们查询到您近期每个月流量都不太够用，办理后您每个月只需多花费不到十块钱。 | M25: 好的，那你给我办理吧 | N25: 4 | O25: 好的，那我现在为您办理，办理后您的资费是下周期1号生效，活动也于下周期1号生效，为您赠送的话费会在下月起每月底前直接返还到您的账户上，活动有效期24个月，到期后我们会再与您联系。 | P25: 好的，那你给我办理吧 | Q25: 5
A26: 36 | B26: 79元资费月返23元话费金币活动（24个月） | C26: 为您申请的是79元资费，包含20GB流量，300分钟语音，并且为您申请了优惠，您办理后，每月为您返还23元话费，您每月只需花费56元。 | D26: 我再等等办理吧，我应该用不到这么高套餐 | E26: 5 | F26: 您现在变更79元资费，可参加月返23元话费活动，优惠完您每个月56元就可以享受原本79元的内容。 | G26: 我再等等办理吧，我应该用不到这么高套餐 | H26: 4 | I26: 我们查询到您近期的套内流量基本不够用，您在办理了申请的政策后，仅需多花几块钱就可以多享受20GB流量，这样您的其他卡就可以将资费便宜一些也够您用，这样算下来反而比您现在的总花费更少了。 | J26: 好的，那你给我办理吧 | K26: 5 | L26: 为您申请的政策是根据您近期消费及流量使用情况制定的，我们查询到您近期每个月流量都不太够用，办理后您每个月只需多花费不到十块钱。 | M26: 好的，那你给我办理吧 | N26: 4 | O26: 好的，那我现在为您办理，办理后您的资费是下周期1号生效，活动也于下周期1号生效，为您赠送的话费会在下月起每月底前直接返还到您的账户上，活动有效期24个月，到期后我们会再与您联系。 | P26: 好的，那你给我办理吧 | Q26: 5
A27: 37 | B27: 99元资费月返29元话费金币活动（24个月） | C27: 为您申请的是99元资费，包含20GB流量，500分钟语音，并且为您申请了优惠，您办理后，每月为您返还29元话费，您每月只需花费70元。 | D27: 我再等等办理吧，我应该用不到这么高套餐 | E27: 5 | F27: 您现在变更99元资费，可参加月返26元话费活动，优惠完您每个月73元就可以享受原本99元的内容。 | G27: 我再等等办理吧，我应该用不到这么高套餐 | H27: 4 | I27: 我们查询到您近期的套内流量基本不够用，您在办理了申请的政策后，仅需多花几块钱就可以多享受20GB流量，这样您的其他卡就可以将资费便宜一些也够您用，这样算下来反而比您现在的总花费更少了。 | J27: 好的，那你给我办理吧 | K27: 5 | L27: 为您申请的政策是根据您近期消费及流量使用情况制定的，我们查询到您近期每个月流量都不太够用，办理后您每个月只需多花费不到十块钱。 | M27: 好的，那你给我办理吧 | N27: 4 | O27: 好的，那我现在为您办理，办理后您的资费是下周期1号生效，活动也于下周期1号生效，为您赠送的话费会在下月起每月底前直接返还到您的账户上，活动有效期24个月，到期后我们会再与您联系。 | P27: 好的，那你给我办理吧 | Q27: 5
A28: 38 | B28: 129元资费月返38元话费金币活动（24个月） | C28: 为您申请的是129元资费，包含30GB流量，500分钟语音，并且为您申请了优惠，您办理后，每月为您返还38元话费，您每月只需花费91元。 | D28: 我再等等办理吧，我应该用不到这么高套餐 | E28: 5 | F28: 您现在变更129元资费，可参加月返38元话费活动，优惠完您每个月91元就可以享受原本129元的内容。 | G28: 我再等等办理吧，我应该用不到这么高套餐 | H28: 4 | I28: 我们查询到您近期的套内流量基本不够用，您在办理了申请的政策后，仅需多花几块钱就可以多享受30GB流量，这样您的其他卡就可以将资费便宜一些也够您用，这样算下来反而比您现在的总花费更少了。 | J28: 好的，那你给我办理吧 | K28: 5 | L28: 为您申请的政策是根据您近期消费及流量使用情况制定的，我们查询到您近期每个月流量都不太够用，办理后您每个月只需多花费不到十块钱。 | M28: 好的，那你给我办理吧 | N28: 4 | O28: 好的，那我现在为您办理，办理后您的资费是下周期1号生效，活动也于下周期1号生效，为您赠送的话费会在下月起每月底前直接返还到您的账户上，活动有效期24个月，到期后我们会再与您联系。 | P28: 好的，那你给我办理吧 | Q28: 5
... A37: 47 | B37: 69元视频卡 | C37: 根据您的语音流量需求，每个月都会产生一点超套费用，现在有个视频卡资费很适合您，每月69元即可享受300分钟通话，20GB通用流量及15GB专属APP流量，看您平时看抖音还是看快手比较多，为您选择一下，而且还包含黑卡权益，可以在咱们当地加油、吃饭的时候有优惠呢。 | D37: 有点贵，我之前资费才50左右 | E37: 5 | F37: 这档资费真的很适合您，每月69元即可享受20GB通用流量，300分钟通话15GB专属APP流量，您每月仅需多花20元即可办理享受。 | G37: 有点贵，专属APP是指什么？ | H37: 4 | I37: 为您申请的政策是根据您近期消费及流量使用情况制定的，您现在每个月流量使用都在20GB左右，很容易超套，您每个月也有超套费用，流量超套之后是按照5元/GB收取的。您每个月只需多花费不到20块钱，就可以享受到这个活动。看热门视频软件的时候就不怕流量超套了。 | J37: 那行吧 | K37: 5 | L37: 这个政策比常规政策要优惠很多，包含的资源也要比正常资费多，您也先体验一下。 | M37: 那我试试吧 | N37: 4 | O37: 好的，那我现在为您办理，办理后您的资费是立即生效，活动也于立即生效，基础套餐月使用费按天折算收取，套餐内包含内容按天折算提供，按日计费进行扣费，到期后我们会再与您联系。 | P37: 嗯嗯 | Q37: 5
